INFO:     Will watch for changes in these directories: ['/home/daniel/Documents/user-service']
INFO:     Uvicorn running on http://0.0.0.0:8000 (Press CTRL+C to quit)
INFO:     Started reloader process [4954] using WatchFiles
INFO:     Started server process [4957]
INFO:     Waiting for application startup.
INFO:     Application startup complete.
✅ Auth router imported successfully
✅ RBAC router imported successfully
✅ Auth router included in FastAPI app
✅ RBAC router included in FastAPI app
INFO:     127.0.0.1:37572 - "GET /health HTTP/1.1" 200 OK
INFO:     127.0.0.1:55750 - "POST /api/v1/auth/login HTTP/1.1" 500 Internal Server Error
ERROR:    Exception in ASGI application
Traceback (most recent call last):
  File "/home/daniel/Documents/venv/lib/python3.13/site-packages/sqlalchemy/engine/base.py", line 143, in __init__
    self._dbapi_connection = engine.raw_connection()
                             ~~~~~~~~~~~~~~~~~~~~~^^
  File "/home/daniel/Documents/venv/lib/python3.13/site-packages/sqlalchemy/engine/base.py", line 3301, in raw_connection
    return self.pool.connect()
           ~~~~~~~~~~~~~~~~~^^
  File "/home/daniel/Documents/venv/lib/python3.13/site-packages/sqlalchemy/pool/base.py", line 447, in connect
    return _ConnectionFairy._checkout(self)
           ~~~~~~~~~~~~~~~~~~~~~~~~~~^^^^^^
  File "/home/daniel/Documents/venv/lib/python3.13/site-packages/sqlalchemy/pool/base.py", line 1264, in _checkout
    fairy = _ConnectionRecord.checkout(pool)
  File "/home/daniel/Documents/venv/lib/python3.13/site-packages/sqlalchemy/pool/base.py", line 711, in checkout
    rec = pool._do_get()
  File "/home/daniel/Documents/venv/lib/python3.13/site-packages/sqlalchemy/pool/impl.py", line 177, in _do_get
    with util.safe_reraise():
         ~~~~~~~~~~~~~~~~~^^
  File "/home/daniel/Documents/venv/lib/python3.13/site-packages/sqlalchemy/util/langhelpers.py", line 224, in __exit__
    raise exc_value.with_traceback(exc_tb)
  File "/home/daniel/Documents/venv/lib/python3.13/site-packages/sqlalchemy/pool/impl.py", line 175, in _do_get
    return self._create_connection()
           ~~~~~~~~~~~~~~~~~~~~~~~^^
  File "/home/daniel/Documents/venv/lib/python3.13/site-packages/sqlalchemy/pool/base.py", line 388, in _create_connection
    return _ConnectionRecord(self)
  File "/home/daniel/Documents/venv/lib/python3.13/site-packages/sqlalchemy/pool/base.py", line 673, in __init__
    self.__connect()
    ~~~~~~~~~~~~~~^^
  File "/home/daniel/Documents/venv/lib/python3.13/site-packages/sqlalchemy/pool/base.py", line 899, in __connect
    with util.safe_reraise():
         ~~~~~~~~~~~~~~~~~^^
  File "/home/daniel/Documents/venv/lib/python3.13/site-packages/sqlalchemy/util/langhelpers.py", line 224, in __exit__
    raise exc_value.with_traceback(exc_tb)
  File "/home/daniel/Documents/venv/lib/python3.13/site-packages/sqlalchemy/pool/base.py", line 895, in __connect
    self.dbapi_connection = connection = pool._invoke_creator(self)
                                         ~~~~~~~~~~~~~~~~~~~~^^^^^^
  File "/home/daniel/Documents/venv/lib/python3.13/site-packages/sqlalchemy/engine/create.py", line 661, in connect
    return dialect.connect(*cargs, **cparams)
           ~~~~~~~~~~~~~~~^^^^^^^^^^^^^^^^^^^
  File "/home/daniel/Documents/venv/lib/python3.13/site-packages/sqlalchemy/engine/default.py", line 629, in connect
    return self.loaded_dbapi.connect(*cargs, **cparams)  # type: ignore[no-any-return]  # NOQA: E501
           ~~~~~~~~~~~~~~~~~~~~~~~~~^^^^^^^^^^^^^^^^^^^
  File "/home/daniel/Documents/venv/lib/python3.13/site-packages/psycopg2/__init__.py", line 122, in connect
    conn = _connect(dsn, connection_factory=connection_factory, **kwasync)
psycopg2.OperationalError: connection to server at "localhost" (::1), port 5432 failed: Connection refused
	Is the server running on that host and accepting TCP/IP connections?
connection to server at "localhost" (127.0.0.1), port 5432 failed: Connection refused
	Is the server running on that host and accepting TCP/IP connections?


The above exception was the direct cause of the following exception:

Traceback (most recent call last):
  File "/home/daniel/Documents/venv/lib/python3.13/site-packages/uvicorn/protocols/http/httptools_impl.py", line 426, in run_asgi
    result = await app(  # type: ignore[func-returns-value]
             ^^^^^^^^^^^^^^^^^^^^^^^^^^^^^^^^^^^^^^^^^^^^^^
        self.scope, self.receive, self.send
        ^^^^^^^^^^^^^^^^^^^^^^^^^^^^^^^^^^^
    )
    ^
  File "/home/daniel/Documents/venv/lib/python3.13/site-packages/uvicorn/middleware/proxy_headers.py", line 84, in __call__
    return await self.app(scope, receive, send)
           ^^^^^^^^^^^^^^^^^^^^^^^^^^^^^^^^^^^^
  File "/home/daniel/Documents/venv/lib/python3.13/site-packages/fastapi/applications.py", line 1133, in __call__
    await super().__call__(scope, receive, send)
  File "/home/daniel/Documents/venv/lib/python3.13/site-packages/starlette/applications.py", line 113, in __call__
    await self.middleware_stack(scope, receive, send)
  File "/home/daniel/Documents/venv/lib/python3.13/site-packages/starlette/middleware/errors.py", line 186, in __call__
    raise exc
  File "/home/daniel/Documents/venv/lib/python3.13/site-packages/starlette/middleware/errors.py", line 164, in __call__
    await self.app(scope, receive, _send)
  File "/home/daniel/Documents/venv/lib/python3.13/site-packages/starlette/middleware/cors.py", line 85, in __call__
    await self.app(scope, receive, send)
  File "/home/daniel/Documents/venv/lib/python3.13/site-packages/starlette/middleware/exceptions.py", line 63, in __call__
    await wrap_app_handling_exceptions(self.app, conn)(scope, receive, send)
  File "/home/daniel/Documents/venv/lib/python3.13/site-packages/starlette/_exception_handler.py", line 53, in wrapped_app
    raise exc
  File "/home/daniel/Documents/venv/lib/python3.13/site-packages/starlette/_exception_handler.py", line 42, in wrapped_app
    await app(scope, receive, sender)
  File "/home/daniel/Documents/venv/lib/python3.13/site-packages/fastapi/middleware/asyncexitstack.py", line 18, in __call__
    await self.app(scope, receive, send)
  File "/home/daniel/Documents/venv/lib/python3.13/site-packages/starlette/routing.py", line 716, in __call__
    await self.middleware_stack(scope, receive, send)
  File "/home/daniel/Documents/venv/lib/python3.13/site-packages/starlette/routing.py", line 736, in app
    await route.handle(scope, receive, send)
  File "/home/daniel/Documents/venv/lib/python3.13/site-packages/starlette/routing.py", line 290, in handle
    await self.app(scope, receive, send)
  File "/home/daniel/Documents/venv/lib/python3.13/site-packages/fastapi/routing.py", line 123, in app
    await wrap_app_handling_exceptions(app, request)(scope, receive, send)
  File "/home/daniel/Documents/venv/lib/python3.13/site-packages/starlette/_exception_handler.py", line 53, in wrapped_app
    raise exc
  File "/home/daniel/Documents/venv/lib/python3.13/site-packages/starlette/_exception_handler.py", line 42, in wrapped_app
    await app(scope, receive, sender)
  File "/home/daniel/Documents/venv/lib/python3.13/site-packages/fastapi/routing.py", line 109, in app
    response = await f(request)
               ^^^^^^^^^^^^^^^^
  File "/home/daniel/Documents/venv/lib/python3.13/site-packages/fastapi/routing.py", line 387, in app
    raw_response = await run_endpoint_function(
                   ^^^^^^^^^^^^^^^^^^^^^^^^^^^^
    ...<3 lines>...
    )
    ^
  File "/home/daniel/Documents/venv/lib/python3.13/site-packages/fastapi/routing.py", line 288, in run_endpoint_function
    return await dependant.call(**values)
           ^^^^^^^^^^^^^^^^^^^^^^^^^^^^^^
  File "/home/daniel/Documents/user-service/app/api/v1/endpoints/auth.py", line 36, in login
    ).first()
      ~~~~~^^
  File "/home/daniel/Documents/venv/lib/python3.13/site-packages/sqlalchemy/orm/query.py", line 2759, in first
    return self.limit(1)._iter().first()  # type: ignore
           ~~~~~~~~~~~~~~~~~~~^^
  File "/home/daniel/Documents/venv/lib/python3.13/site-packages/sqlalchemy/orm/query.py", line 2857, in _iter
    result: Union[ScalarResult[_T], Result[_T]] = self.session.execute(
                                                  ~~~~~~~~~~~~~~~~~~~~^
        statement,
        ^^^^^^^^^^
        params,
        ^^^^^^^
        execution_options={"_sa_orm_load_options": self.load_options},
        ^^^^^^^^^^^^^^^^^^^^^^^^^^^^^^^^^^^^^^^^^^^^^^^^^^^^^^^^^^^^^^
    )
    ^
  File "/home/daniel/Documents/venv/lib/python3.13/site-packages/sqlalchemy/orm/session.py", line 2365, in execute
    return self._execute_internal(
           ~~~~~~~~~~~~~~~~~~~~~~^
        statement,
        ^^^^^^^^^^
    ...<4 lines>...
        _add_event=_add_event,
        ^^^^^^^^^^^^^^^^^^^^^^
    )
    ^
  File "/home/daniel/Documents/venv/lib/python3.13/site-packages/sqlalchemy/orm/session.py", line 2241, in _execute_internal
    conn = self._connection_for_bind(bind)
  File "/home/daniel/Documents/venv/lib/python3.13/site-packages/sqlalchemy/orm/session.py", line 2110, in _connection_for_bind
    return trans._connection_for_bind(engine, execution_options)
           ~~~~~~~~~~~~~~~~~~~~~~~~~~^^^^^^^^^^^^^^^^^^^^^^^^^^^
  File "<string>", line 2, in _connection_for_bind
  File "/home/daniel/Documents/venv/lib/python3.13/site-packages/sqlalchemy/orm/state_changes.py", line 137, in _go
    ret_value = fn(self, *arg, **kw)
  File "/home/daniel/Documents/venv/lib/python3.13/site-packages/sqlalchemy/orm/session.py", line 1189, in _connection_for_bind
    conn = bind.connect()
  File "/home/daniel/Documents/venv/lib/python3.13/site-packages/sqlalchemy/engine/base.py", line 3277, in connect
    return self._connection_cls(self)
           ~~~~~~~~~~~~~~~~~~~~^^^^^^
  File "/home/daniel/Documents/venv/lib/python3.13/site-packages/sqlalchemy/engine/base.py", line 145, in __init__
    Connection._handle_dbapi_exception_noconnection(
    ~~~~~~~~~~~~~~~~~~~~~~~~~~~~~~~~~~~~~~~~~~~~~~~^
        err, dialect, engine
        ^^^^^^^^^^^^^^^^^^^^
    )
    ^
  File "/home/daniel/Documents/venv/lib/python3.13/site-packages/sqlalchemy/engine/base.py", line 2440, in _handle_dbapi_exception_noconnection
    raise sqlalchemy_exception.with_traceback(exc_info[2]) from e
  File "/home/daniel/Documents/venv/lib/python3.13/site-packages/sqlalchemy/engine/base.py", line 143, in __init__
    self._dbapi_connection = engine.raw_connection()
                             ~~~~~~~~~~~~~~~~~~~~~^^
  File "/home/daniel/Documents/venv/lib/python3.13/site-packages/sqlalchemy/engine/base.py", line 3301, in raw_connection
    return self.pool.connect()
           ~~~~~~~~~~~~~~~~~^^
  File "/home/daniel/Documents/venv/lib/python3.13/site-packages/sqlalchemy/pool/base.py", line 447, in connect
    return _ConnectionFairy._checkout(self)
           ~~~~~~~~~~~~~~~~~~~~~~~~~~^^^^^^
  File "/home/daniel/Documents/venv/lib/python3.13/site-packages/sqlalchemy/pool/base.py", line 1264, in _checkout
    fairy = _ConnectionRecord.checkout(pool)
  File "/home/daniel/Documents/venv/lib/python3.13/site-packages/sqlalchemy/pool/base.py", line 711, in checkout
    rec = pool._do_get()
  File "/home/daniel/Documents/venv/lib/python3.13/site-packages/sqlalchemy/pool/impl.py", line 177, in _do_get
    with util.safe_reraise():
         ~~~~~~~~~~~~~~~~~^^
  File "/home/daniel/Documents/venv/lib/python3.13/site-packages/sqlalchemy/util/langhelpers.py", line 224, in __exit__
    raise exc_value.with_traceback(exc_tb)
  File "/home/daniel/Documents/venv/lib/python3.13/site-packages/sqlalchemy/pool/impl.py", line 175, in _do_get
    return self._create_connection()
           ~~~~~~~~~~~~~~~~~~~~~~~^^
  File "/home/daniel/Documents/venv/lib/python3.13/site-packages/sqlalchemy/pool/base.py", line 388, in _create_connection
    return _ConnectionRecord(self)
  File "/home/daniel/Documents/venv/lib/python3.13/site-packages/sqlalchemy/pool/base.py", line 673, in __init__
    self.__connect()
    ~~~~~~~~~~~~~~^^
  File "/home/daniel/Documents/venv/lib/python3.13/site-packages/sqlalchemy/pool/base.py", line 899, in __connect
    with util.safe_reraise():
         ~~~~~~~~~~~~~~~~~^^
  File "/home/daniel/Documents/venv/lib/python3.13/site-packages/sqlalchemy/util/langhelpers.py", line 224, in __exit__
    raise exc_value.with_traceback(exc_tb)
  File "/home/daniel/Documents/venv/lib/python3.13/site-packages/sqlalchemy/pool/base.py", line 895, in __connect
    self.dbapi_connection = connection = pool._invoke_creator(self)
                                         ~~~~~~~~~~~~~~~~~~~~^^^^^^
  File "/home/daniel/Documents/venv/lib/python3.13/site-packages/sqlalchemy/engine/create.py", line 661, in connect
    return dialect.connect(*cargs, **cparams)
           ~~~~~~~~~~~~~~~^^^^^^^^^^^^^^^^^^^
  File "/home/daniel/Documents/venv/lib/python3.13/site-packages/sqlalchemy/engine/default.py", line 629, in connect
    return self.loaded_dbapi.connect(*cargs, **cparams)  # type: ignore[no-any-return]  # NOQA: E501
           ~~~~~~~~~~~~~~~~~~~~~~~~~^^^^^^^^^^^^^^^^^^^
  File "/home/daniel/Documents/venv/lib/python3.13/site-packages/psycopg2/__init__.py", line 122, in connect
    conn = _connect(dsn, connection_factory=connection_factory, **kwasync)
sqlalchemy.exc.OperationalError: (psycopg2.OperationalError) connection to server at "localhost" (::1), port 5432 failed: Connection refused
	Is the server running on that host and accepting TCP/IP connections?
connection to server at "localhost" (127.0.0.1), port 5432 failed: Connection refused
	Is the server running on that host and accepting TCP/IP connections?

(Background on this error at: https://sqlalche.me/e/20/e3q8)
INFO:     Shutting down
INFO:     Waiting for application shutdown.
INFO:     Application shutdown complete.
INFO:     Finished server process [4957]
INFO:     Stopping reloader process [4954]
